#!/usr/bin/env python



from __future__ import print_function

import os
import json
import sys
import traceback
from urllib.parse import urlparse
from urllib.request import urlopen

import boto3
import botocore

import papermill

input_var = "PAPERMILL_INPUT"
output_var = "PAPERMILL_OUTPUT"
params_var = "PAPERMILL_PARAMS"


def run_notebook():
    try:
        notebook = os.environ[input_var]
        output_notebook = os.environ[output_var]
        params = json.loads(os.environ[params_var])

        notebook_dir = os.path.dirname(notebook)
        notebook_file = os.path.basename(notebook)

        # If the user specified notebook path in S3, run with that path.
        if notebook.startswith("s3://"):
            print("Downloading notebook {}".format(notebook))
            o = urlparse(notebook)
            bucket = o.netloc
            key = o.path[1:]

            s3 = boto3.resource("s3")

            try:
                s3.Bucket(bucket).download_file(key, "/tmp/" + notebook_file)
                notebook_dir = "/tmp"
            except botocore.exceptions.ClientError as e:
                if e.response["Error"]["Code"] == "404":
                    print("The notebook {} does not exist.".format(notebook))
                raise
            print("Download complete")

        os.chdir(notebook_dir)

        print("Executing {} with output to {}".format(notebook_file, output_notebook))
        print("Notebook params = {}".format(params))
        papermill.execute_notebook(
            notebook_file, output_notebook, params, kernel_name="python3"
        )
        print("Execution complete")

    except Exception as e:
        # Write out an error file. This will be returned as the failureReason in the
        # DescribeProcessingJob result.
        trc = traceback.format_exc()
        # with open(os.path.join(output_path, 'failure'), 'w') as s:
        #    s.write('Exception during processing: ' + str(e) + '\n' + trc)
        # Printing this causes the exception to be in the training job logs, as well.
        print("Exception during processing: " + str(e) + "\n" + trc, file=sys.stderr)
        # A non-zero exit code causes the training job to be marked as Failed.
        # sys.exit(255)
        output_notebook = "xyzzy"  # Dummy for print, below

    if not os.path.exists(output_notebook):
        print("No output notebook was generated")
    else:
        print("Output was written to {}".format(output_notebook))


if __name__ == "__main__":
    run_notebook()
